[2021-02-14 15:46:21,623] {taskinstance.py:851} INFO - Dependencies all met for <TaskInstance: NDBC_51001.clean_and_load 2021-02-15T01:46:15.095576+00:00 [queued]>
[2021-02-14 15:46:21,627] {taskinstance.py:851} INFO - Dependencies all met for <TaskInstance: NDBC_51001.clean_and_load 2021-02-15T01:46:15.095576+00:00 [queued]>
[2021-02-14 15:46:21,627] {taskinstance.py:1042} INFO - 
--------------------------------------------------------------------------------
[2021-02-14 15:46:21,627] {taskinstance.py:1043} INFO - Starting attempt 1 of 1
[2021-02-14 15:46:21,627] {taskinstance.py:1044} INFO - 
--------------------------------------------------------------------------------
[2021-02-14 15:46:21,633] {taskinstance.py:1063} INFO - Executing <Task(PythonOperator): clean_and_load> on 2021-02-15T01:46:15.095576+00:00
[2021-02-14 15:46:21,635] {standard_task_runner.py:52} INFO - Started process 93591 to run task
[2021-02-14 15:46:21,641] {standard_task_runner.py:76} INFO - Running: ['airflow', 'tasks', 'run', 'NDBC_51001', 'clean_and_load', '2021-02-15T01:46:15.095576+00:00', '--job-id', '28', '--pool', 'default_pool', '--raw', '--subdir', 'DAGS_FOLDER/ndbc_dag.py', '--cfg-path', '/var/folders/y8/ykx6qdr96dldyw_z287s5l580000gn/T/tmp_276_ih9', '--error-file', '/var/folders/y8/ykx6qdr96dldyw_z287s5l580000gn/T/tmppxgtn9rx']
[2021-02-14 15:46:21,643] {standard_task_runner.py:77} INFO - Job 28: Subtask clean_and_load
[2021-02-14 15:46:21,670] {logging_mixin.py:104} INFO - Running <TaskInstance: NDBC_51001.clean_and_load 2021-02-15T01:46:15.095576+00:00 [running]> on host chriss-mbp.lan1
[2021-02-14 15:46:21,688] {taskinstance.py:1255} INFO - Exporting the following env vars:
AIRFLOW_CTX_DAG_EMAIL=holloway.christopher.t@gmail.com
AIRFLOW_CTX_DAG_OWNER=chris
AIRFLOW_CTX_DAG_ID=NDBC_51001
AIRFLOW_CTX_TASK_ID=clean_and_load
AIRFLOW_CTX_EXECUTION_DATE=2021-02-15T01:46:15.095576+00:00
AIRFLOW_CTX_DAG_RUN_ID=manual__2021-02-15T01:46:15.095576+00:00
[2021-02-14 15:46:22,116] {base.py:65} INFO - Using connection to: id: NDBC_51001. Host: localhost, Port: 5400, Schema: NDBC_51001DB, Login: chrisholloway, Password: None, extra: None
[2021-02-14 15:46:22,122] {dbapi.py:180} INFO - Running statement: INSERT INTO Detailed_Wave_Data_Table (significant_wave_height, swell_height, swell_period, wind_wave_period,
	 wind_wave_height, wind_wave_period, average_period) VALUES (%f, %f, %f, %f, %f, %f, %f);, parameters: (0       2.9
1       2.7
2       3.1
3       2.7
4       2.7
       ... 
1070    3.9
1071    4.1
1072    4.5
1073    4.4
1074    3.8
Name: WVHT, Length: 1075, dtype: float64, 0       2.9
1       2.6
2       3.0
3       2.7
4       2.6
       ... 
1070    3.7
1071    3.9
1072    4.3
1073    4.2
1074    3.5
Name: SwH, Length: 1075, dtype: float64, 0       13.8
1       13.8
2       13.8
3       13.8
4       14.8
        ... 
1070    14.8
1071    16.0
1072    16.0
1073    16.0
1074    13.8
Name: SwP, Length: 1075, dtype: float64, 0       4.8
1       4.3
2       4.3
3       4.2
4       3.8
       ... 
1070    6.2
1071    5.0
1072    5.9
1073    5.6
1074    5.9
Name: WWP, Length: 1075, dtype: float64, 0       0.6
1       0.4
2       0.5
3       0.4
4       0.4
       ... 
1070    1.3
1071    1.3
1072    1.1
1073    1.3
1074    1.3
Name: WWH, Length: 1075, dtype: float64, 0       4.8
1       4.3
2       4.3
3       4.2
4       3.8
       ... 
1070    6.2
1071    5.0
1072    5.9
1073    5.6
1074    5.9
Name: WWP, Length: 1075, dtype: float64, 0        9.5
1        9.3
2       10.0
3        9.7
4        9.2
        ... 
1070     9.3
1071     9.7
1072    10.6
1073    10.0
1074     9.2
Name: APD, Length: 1075, dtype: float64)
[2021-02-14 15:46:22,130] {taskinstance.py:1455} ERROR - can't adapt type 'Series'
Traceback (most recent call last):
  File "/Users/chrisholloway/opt/anaconda3/lib/python3.8/site-packages/airflow/models/taskinstance.py", line 1112, in _run_raw_task
    self._prepare_and_execute_task_with_callbacks(context, task)
  File "/Users/chrisholloway/opt/anaconda3/lib/python3.8/site-packages/airflow/models/taskinstance.py", line 1285, in _prepare_and_execute_task_with_callbacks
    result = self._execute_task(context, task_copy)
  File "/Users/chrisholloway/opt/anaconda3/lib/python3.8/site-packages/airflow/models/taskinstance.py", line 1315, in _execute_task
    result = task_copy.execute(context=context)
  File "/Users/chrisholloway/opt/anaconda3/lib/python3.8/site-packages/airflow/operators/python.py", line 117, in execute
    return_value = self.execute_callable()
  File "/Users/chrisholloway/opt/anaconda3/lib/python3.8/site-packages/airflow/operators/python.py", line 128, in execute_callable
    return self.python_callable(*self.op_args, **self.op_kwargs)
  File "/Users/chrisholloway/airflow/dags/ndbc_dag.py", line 52, in clean_load_data
    pg_hook.run(insert_cmd, parameters=row)
  File "/Users/chrisholloway/opt/anaconda3/lib/python3.8/site-packages/airflow/hooks/dbapi.py", line 182, in run
    cur.execute(sql_statement, parameters)
psycopg2.ProgrammingError: can't adapt type 'Series'
[2021-02-14 15:46:22,133] {taskinstance.py:1496} INFO - Marking task as FAILED. dag_id=NDBC_51001, task_id=clean_and_load, execution_date=20210215T014615, start_date=20210215T014621, end_date=20210215T014622
[2021-02-14 15:46:22,172] {local_task_job.py:146} INFO - Task exited with return code 1
